batch_size: 28
train_steps: 16
context length: 250
num_tasks: 40
File size: 97266637 bytes
File loaded successfully
File size: 648612 bytes
File loaded successfully
output_dir: ../outputs/GPT2/240620_210703.31028a_upperTriA_gauss_C
checkpoint_callback /home/sultand/mop_modifications/streamlined_mop/outputs/GPT2/240620_210703.31028a_upperTriA_gauss_C/checkpoints
ckpt_path: ../outputs/GPT2/240620_210703.31028a_upperTriA_gauss_C/checkpoints/step=16.ckpt
Traceback (most recent call last):
  File "/home/sultand/mop_modifications/streamlined_mop/src/data_train.py", line 122, in <module>
    train_gpt2(model, config, output_dir) # train the model
    ^^^^^^^^^^^^^^^^^^^^^^^^^^^^^^^^^^^^^
  File "/home/sultand/mop_modifications/streamlined_mop/src/train.py", line 51, in train_gpt2
    trainer = pl.Trainer(
              ^^^^^^^^^^^
  File "/home/sultand/.conda/envs/mop/lib/python3.12/site-packages/pytorch_lightning/utilities/argparse.py", line 70, in insert_env_defaults
    return fn(self, **kwargs)
           ^^^^^^^^^^^^^^^^^^
  File "/home/sultand/.conda/envs/mop/lib/python3.12/site-packages/pytorch_lightning/trainer/trainer.py", line 400, in __init__
    self._accelerator_connector = _AcceleratorConnector(
                                  ^^^^^^^^^^^^^^^^^^^^^^
  File "/home/sultand/.conda/envs/mop/lib/python3.12/site-packages/pytorch_lightning/trainer/connectors/accelerator_connector.py", line 145, in __init__
    self._check_device_config_and_set_final_flags(devices=devices, num_nodes=num_nodes)
  File "/home/sultand/.conda/envs/mop/lib/python3.12/site-packages/pytorch_lightning/trainer/connectors/accelerator_connector.py", line 326, in _check_device_config_and_set_final_flags
    raise MisconfigurationException(
lightning_fabric.utilities.exceptions.MisconfigurationException: `Trainer(devices=0)` value is not a valid input using cuda accelerator.