batch_size: 28
train_steps: 16
context length: 250
num_tasks: 40
output_dir: ../outputs/GPT2/240625_001450.84f787_upperTriA_gauss_C
checkpoint_callback /home/sultand/mop_modifications/streamlined_mop/outputs/GPT2/240625_001450.84f787_upperTriA_gauss_C/checkpoints
ckpt_path: ../outputs/GPT2/240625_001450.84f787_upperTriA_gauss_C/checkpoints/step=16.ckpt
Checkpoint file ../outputs/GPT2/240625_001450.84f787_upperTriA_gauss_C/checkpoints/step=16.ckpt does not exist.
Initializing distributed: GLOBAL_RANK: 2, MEMBER: 3/4
LOCAL_RANK: 2 - CUDA_VISIBLE_DEVICES: [0,1,2,3]
[rank2]: Traceback (most recent call last):
[rank2]:   File "/home/sultand/mop_modifications/streamlined_mop/src/data_train.py", line 135, in <module>
[rank2]:     create_plots(config, run_preds, run_deg_kf_test, excess, num_systems=config.num_val_tasks, shade=shade)
[rank2]:   File "/home/sultand/mop_modifications/streamlined_mop/src/create_plots_with_zero_pred.py", line 587, in create_plots
[rank2]:     save_preds(run_deg_kf_test, config) #save the predictions to a file
[rank2]:     ^^^^^^^^^^^^^^^^^^^^^^^^^^^^^^^^^^^
[rank2]:   File "/home/sultand/mop_modifications/streamlined_mop/src/create_plots_with_zero_pred.py", line 472, in save_preds
[rank2]:     err_lss, irreducible_error = compute_errors(config, config.C_dist, run_deg_kf_test, wentinn_data=False)  #, emb_dim)
[rank2]:                                  ^^^^^^^^^^^^^^^^^^^^^^^^^^^^^^^^^^^^^^^^^^^^^^^^^^^^^^^^^^^^^^^^^^^^^^^^^^
[rank2]:   File "/home/sultand/mop_modifications/streamlined_mop/src/create_plots_with_zero_pred.py", line 205, in compute_errors
[rank2]:     model = GPT2.load_from_checkpoint(config.ckpt_path,
[rank2]:             ^^^^^^^^^^^^^^^^^^^^^^^^^^^^^^^^^^^^^^^^^^^
[rank2]:   File "/home/sultand/.conda/envs/mop/lib/python3.12/site-packages/pytorch_lightning/utilities/model_helpers.py", line 125, in wrapper
[rank2]:     return self.method(cls, *args, **kwargs)
[rank2]:            ^^^^^^^^^^^^^^^^^^^^^^^^^^^^^^^^^
[rank2]:   File "/home/sultand/.conda/envs/mop/lib/python3.12/site-packages/pytorch_lightning/core/module.py", line 1586, in load_from_checkpoint
ckpt_path ../outputs/GPT2/240625_001450.84f787_upperTriA_gauss_C/checkpoints/step=16.ckpt
config path: ../outputs/GPT2/240625_001450.84f787_upperTriA_gauss_C/checkpoints/step=16.ckpt
Number of validation systems: 3
Number of traces: 2